INFO:aiogram:Bot: gmp_test [@gmp_test_bot]
INFO:aiogram.dispatcher.dispatcher:Start polling.
INFO:root:1404452814 Artur Tue Mar  7 01:38:28 2023
INFO:root:1404452814 Artur Tue Mar  7 01:41:05 2023
INFO:aiogram:Bot: gmp_test [@gmp_test_bot]
INFO:aiogram.dispatcher.dispatcher:Start polling.
INFO:root:1404452814 Artur Wed Mar  8 20:25:52 2023
INFO:aiogram:Bot: gmp_test [@gmp_test_bot]
INFO:aiogram.dispatcher.dispatcher:Start polling.
INFO:root:1404452814 Artur Wed Mar  8 20:42:25 2023
INFO:aiogram:Bot: gmp_test [@gmp_test_bot]
INFO:aiogram.dispatcher.dispatcher:Start polling.
INFO:root:1404452814 Artur Wed Mar  8 21:04:28 2023
INFO:root:1404452814 Artur Wed Mar  8 21:04:28 2023
INFO:aiogram:Bot: gmp_test [@gmp_test_bot]
INFO:aiogram.dispatcher.dispatcher:Start polling.
INFO:root:1404452814 Artur Wed Mar  8 21:33:19 2023
INFO:root:1404452814 Artur Wed Mar  8 21:33:31 2023
INFO:aiogram:Bot: gmp_test [@gmp_test_bot]
INFO:aiogram.dispatcher.dispatcher:Start polling.
INFO:root:1404452814 Artur Wed Mar  8 22:12:11 2023
ERROR:asyncio:Task exception was never retrieved
future: <Task finished name='Task-17' coro=<Dispatcher._process_polling_updates() done, defined at c:\Python\telegram\GMP-Warranty_ID_bot\venv\lib\site-packages\aiogram\dispatcher\dispatcher.py:407> exception=APIError({'code': 400, 'message': 'Invalid value at \'data.values[0]\' (type.googleapis.com/google.protobuf.ListValue), 1404452814\nInvalid value at \'insert_data_option\' (type.googleapis.com/google.apps.sheets.v4.InsertDataOption), "1678302731.9701622"\nInvalid value at \'value_input_option\' (type.googleapis.com/google.apps.sheets.v4.ValueInputOption), "Em003230123W0C"', 'status': 'INVALID_ARGUMENT', 'details': [{'@type': 'type.googleapis.com/google.rpc.BadRequest', 'fieldViolations': [{'field': 'data.values[0]', 'description': "Invalid value at 'data.values[0]' (type.googleapis.com/google.protobuf.ListValue), 1404452814"}, {'field': 'insert_data_option', 'description': 'Invalid value at \'insert_data_option\' (type.googleapis.com/google.apps.sheets.v4.InsertDataOption), "1678302731.9701622"'}, {'field': 'value_input_option', 'description': 'Invalid value at \'value_input_option\' (type.googleapis.com/google.apps.sheets.v4.ValueInputOption), "Em003230123W0C"'}]}]})>
Traceback (most recent call last):
  File "c:\Python\telegram\GMP-Warranty_ID_bot\venv\lib\site-packages\aiogram\dispatcher\dispatcher.py", line 415, in _process_polling_updates
    for responses in itertools.chain.from_iterable(await self.process_updates(updates, fast)):
  File "c:\Python\telegram\GMP-Warranty_ID_bot\venv\lib\site-packages\aiogram\dispatcher\dispatcher.py", line 235, in process_updates
    return await asyncio.gather(*tasks)
  File "c:\Python\telegram\GMP-Warranty_ID_bot\venv\lib\site-packages\aiogram\dispatcher\handler.py", line 117, in notify
    response = await handler_obj.handler(*args, **partial_data)
  File "c:\Python\telegram\GMP-Warranty_ID_bot\venv\lib\site-packages\aiogram\dispatcher\dispatcher.py", line 256, in process_update
    return await self.message_handlers.notify(update.message)
  File "c:\Python\telegram\GMP-Warranty_ID_bot\venv\lib\site-packages\aiogram\dispatcher\handler.py", line 117, in notify
    response = await handler_obj.handler(*args, **partial_data)
  File "C:\Python\telegram\GMP-Warranty_ID_bot\GMP_W_B_main 1.3.py", line 125, in receive_ID_info
    wks.append_row(warranty_state_dictionary['user_no'], warranty_state_dictionary['provide_ID'], [warranty_state_dictionary['session_start_time'],warranty_state_dictionary['query_count']])
  File "c:\Python\telegram\GMP-Warranty_ID_bot\venv\lib\site-packages\gspread\worksheet.py", line 1577, in append_row
    return self.append_rows(
  File "c:\Python\telegram\GMP-Warranty_ID_bot\venv\lib\site-packages\gspread\worksheet.py", line 1627, in append_rows
    return self.spreadsheet.values_append(range_label, params, body)
  File "c:\Python\telegram\GMP-Warranty_ID_bot\venv\lib\site-packages\gspread\spreadsheet.py", line 150, in values_append
    r = self.client.request("post", url, params=params, json=body)
  File "c:\Python\telegram\GMP-Warranty_ID_bot\venv\lib\site-packages\gspread\client.py", line 92, in request
    raise APIError(response)
gspread.exceptions.APIError: {'code': 400, 'message': 'Invalid value at \'data.values[0]\' (type.googleapis.com/google.protobuf.ListValue), 1404452814\nInvalid value at \'insert_data_option\' (type.googleapis.com/google.apps.sheets.v4.InsertDataOption), "1678302731.9701622"\nInvalid value at \'value_input_option\' (type.googleapis.com/google.apps.sheets.v4.ValueInputOption), "Em003230123W0C"', 'status': 'INVALID_ARGUMENT', 'details': [{'@type': 'type.googleapis.com/google.rpc.BadRequest', 'fieldViolations': [{'field': 'data.values[0]', 'description': "Invalid value at 'data.values[0]' (type.googleapis.com/google.protobuf.ListValue), 1404452814"}, {'field': 'insert_data_option', 'description': 'Invalid value at \'insert_data_option\' (type.googleapis.com/google.apps.sheets.v4.InsertDataOption), "1678302731.9701622"'}, {'field': 'value_input_option', 'description': 'Invalid value at \'value_input_option\' (type.googleapis.com/google.apps.sheets.v4.ValueInputOption), "Em003230123W0C"'}]}]}
INFO:root:1404452814 Artur Wed Mar  8 22:12:19 2023
INFO:aiogram:Bot: gmp_test [@gmp_test_bot]
INFO:aiogram.dispatcher.dispatcher:Start polling.
INFO:root:1404452814 Artur Wed Mar  8 22:14:22 2023
ERROR:asyncio:Task exception was never retrieved
future: <Task finished name='Task-17' coro=<Dispatcher._process_polling_updates() done, defined at c:\Python\telegram\GMP-Warranty_ID_bot\venv\lib\site-packages\aiogram\dispatcher\dispatcher.py:407> exception=APIError({'code': 400, 'message': 'Invalid value at \'data.values[0]\' (type.googleapis.com/google.protobuf.ListValue), 1404452814\nInvalid value at \'insert_data_option\' (type.googleapis.com/google.apps.sheets.v4.InsertDataOption), "1678302862.390097"\nInvalid value at \'value_input_option\' (type.googleapis.com/google.apps.sheets.v4.ValueInputOption), "Em003230123W0C"', 'status': 'INVALID_ARGUMENT', 'details': [{'@type': 'type.googleapis.com/google.rpc.BadRequest', 'fieldViolations': [{'field': 'data.values[0]', 'description': "Invalid value at 'data.values[0]' (type.googleapis.com/google.protobuf.ListValue), 1404452814"}, {'field': 'insert_data_option', 'description': 'Invalid value at \'insert_data_option\' (type.googleapis.com/google.apps.sheets.v4.InsertDataOption), "1678302862.390097"'}, {'field': 'value_input_option', 'description': 'Invalid value at \'value_input_option\' (type.googleapis.com/google.apps.sheets.v4.ValueInputOption), "Em003230123W0C"'}]}]})>
Traceback (most recent call last):
  File "c:\Python\telegram\GMP-Warranty_ID_bot\venv\lib\site-packages\aiogram\dispatcher\dispatcher.py", line 415, in _process_polling_updates
    for responses in itertools.chain.from_iterable(await self.process_updates(updates, fast)):
  File "c:\Python\telegram\GMP-Warranty_ID_bot\venv\lib\site-packages\aiogram\dispatcher\dispatcher.py", line 235, in process_updates
    return await asyncio.gather(*tasks)
  File "c:\Python\telegram\GMP-Warranty_ID_bot\venv\lib\site-packages\aiogram\dispatcher\handler.py", line 117, in notify
    response = await handler_obj.handler(*args, **partial_data)
  File "c:\Python\telegram\GMP-Warranty_ID_bot\venv\lib\site-packages\aiogram\dispatcher\dispatcher.py", line 256, in process_update
    return await self.message_handlers.notify(update.message)
  File "c:\Python\telegram\GMP-Warranty_ID_bot\venv\lib\site-packages\aiogram\dispatcher\handler.py", line 117, in notify
    response = await handler_obj.handler(*args, **partial_data)
  File "C:\Python\telegram\GMP-Warranty_ID_bot\GMP_W_B_main 1.3.py", line 125, in receive_ID_info
    wks.append_row(warranty_state_dictionary['user_no'], warranty_state_dictionary['provide_ID'], [warranty_state_dictionary['session_start_time'],warranty_state_dictionary['query_count']])
  File "c:\Python\telegram\GMP-Warranty_ID_bot\venv\lib\site-packages\gspread\worksheet.py", line 1577, in append_row
    return self.append_rows(
  File "c:\Python\telegram\GMP-Warranty_ID_bot\venv\lib\site-packages\gspread\worksheet.py", line 1627, in append_rows
    return self.spreadsheet.values_append(range_label, params, body)
  File "c:\Python\telegram\GMP-Warranty_ID_bot\venv\lib\site-packages\gspread\spreadsheet.py", line 150, in values_append
    r = self.client.request("post", url, params=params, json=body)
  File "c:\Python\telegram\GMP-Warranty_ID_bot\venv\lib\site-packages\gspread\client.py", line 92, in request
    raise APIError(response)
gspread.exceptions.APIError: {'code': 400, 'message': 'Invalid value at \'data.values[0]\' (type.googleapis.com/google.protobuf.ListValue), 1404452814\nInvalid value at \'insert_data_option\' (type.googleapis.com/google.apps.sheets.v4.InsertDataOption), "1678302862.390097"\nInvalid value at \'value_input_option\' (type.googleapis.com/google.apps.sheets.v4.ValueInputOption), "Em003230123W0C"', 'status': 'INVALID_ARGUMENT', 'details': [{'@type': 'type.googleapis.com/google.rpc.BadRequest', 'fieldViolations': [{'field': 'data.values[0]', 'description': "Invalid value at 'data.values[0]' (type.googleapis.com/google.protobuf.ListValue), 1404452814"}, {'field': 'insert_data_option', 'description': 'Invalid value at \'insert_data_option\' (type.googleapis.com/google.apps.sheets.v4.InsertDataOption), "1678302862.390097"'}, {'field': 'value_input_option', 'description': 'Invalid value at \'value_input_option\' (type.googleapis.com/google.apps.sheets.v4.ValueInputOption), "Em003230123W0C"'}]}]}
ERROR:asyncio:Task exception was never retrieved
future: <Task finished name='Task-21' coro=<Dispatcher._process_polling_updates() done, defined at c:\Python\telegram\GMP-Warranty_ID_bot\venv\lib\site-packages\aiogram\dispatcher\dispatcher.py:407> exception=APIError({'code': 400, 'message': 'Invalid value at \'data.values[0]\' (type.googleapis.com/google.protobuf.ListValue), 1404452814\nInvalid value at \'value_input_option\' (type.googleapis.com/google.apps.sheets.v4.ValueInputOption), "asd"\nInvalid value at \'insert_data_option\' (type.googleapis.com/google.apps.sheets.v4.InsertDataOption), "1678302862.390097"\nInvalid value at \'insert_data_option\' (type.googleapis.com/google.apps.sheets.v4.InsertDataOption), "2"', 'status': 'INVALID_ARGUMENT', 'details': [{'@type': 'type.googleapis.com/google.rpc.BadRequest', 'fieldViolations': [{'field': 'data.values[0]', 'description': "Invalid value at 'data.values[0]' (type.googleapis.com/google.protobuf.ListValue), 1404452814"}, {'field': 'value_input_option', 'description': 'Invalid value at \'value_input_option\' (type.googleapis.com/google.apps.sheets.v4.ValueInputOption), "asd"'}, {'field': 'insert_data_option', 'description': 'Invalid value at \'insert_data_option\' (type.googleapis.com/google.apps.sheets.v4.InsertDataOption), "1678302862.390097"'}, {'field': 'insert_data_option', 'description': 'Invalid value at \'insert_data_option\' (type.googleapis.com/google.apps.sheets.v4.InsertDataOption), "2"'}]}]})>
Traceback (most recent call last):
  File "c:\Python\telegram\GMP-Warranty_ID_bot\venv\lib\site-packages\aiogram\dispatcher\dispatcher.py", line 415, in _process_polling_updates
    for responses in itertools.chain.from_iterable(await self.process_updates(updates, fast)):
  File "c:\Python\telegram\GMP-Warranty_ID_bot\venv\lib\site-packages\aiogram\dispatcher\dispatcher.py", line 235, in process_updates
    return await asyncio.gather(*tasks)
  File "c:\Python\telegram\GMP-Warranty_ID_bot\venv\lib\site-packages\aiogram\dispatcher\handler.py", line 117, in notify
    response = await handler_obj.handler(*args, **partial_data)
  File "c:\Python\telegram\GMP-Warranty_ID_bot\venv\lib\site-packages\aiogram\dispatcher\dispatcher.py", line 256, in process_update
    return await self.message_handlers.notify(update.message)
  File "c:\Python\telegram\GMP-Warranty_ID_bot\venv\lib\site-packages\aiogram\dispatcher\handler.py", line 117, in notify
    response = await handler_obj.handler(*args, **partial_data)
  File "C:\Python\telegram\GMP-Warranty_ID_bot\GMP_W_B_main 1.3.py", line 125, in receive_ID_info
    wks.append_row(warranty_state_dictionary['user_no'], warranty_state_dictionary['provide_ID'], [warranty_state_dictionary['session_start_time'],warranty_state_dictionary['query_count']])
  File "c:\Python\telegram\GMP-Warranty_ID_bot\venv\lib\site-packages\gspread\worksheet.py", line 1577, in append_row
    return self.append_rows(
  File "c:\Python\telegram\GMP-Warranty_ID_bot\venv\lib\site-packages\gspread\worksheet.py", line 1627, in append_rows
    return self.spreadsheet.values_append(range_label, params, body)
  File "c:\Python\telegram\GMP-Warranty_ID_bot\venv\lib\site-packages\gspread\spreadsheet.py", line 150, in values_append
    r = self.client.request("post", url, params=params, json=body)
  File "c:\Python\telegram\GMP-Warranty_ID_bot\venv\lib\site-packages\gspread\client.py", line 92, in request
    raise APIError(response)
gspread.exceptions.APIError: {'code': 400, 'message': 'Invalid value at \'data.values[0]\' (type.googleapis.com/google.protobuf.ListValue), 1404452814\nInvalid value at \'value_input_option\' (type.googleapis.com/google.apps.sheets.v4.ValueInputOption), "asd"\nInvalid value at \'insert_data_option\' (type.googleapis.com/google.apps.sheets.v4.InsertDataOption), "1678302862.390097"\nInvalid value at \'insert_data_option\' (type.googleapis.com/google.apps.sheets.v4.InsertDataOption), "2"', 'status': 'INVALID_ARGUMENT', 'details': [{'@type': 'type.googleapis.com/google.rpc.BadRequest', 'fieldViolations': [{'field': 'data.values[0]', 'description': "Invalid value at 'data.values[0]' (type.googleapis.com/google.protobuf.ListValue), 1404452814"}, {'field': 'value_input_option', 'description': 'Invalid value at \'value_input_option\' (type.googleapis.com/google.apps.sheets.v4.ValueInputOption), "asd"'}, {'field': 'insert_data_option', 'description': 'Invalid value at \'insert_data_option\' (type.googleapis.com/google.apps.sheets.v4.InsertDataOption), "1678302862.390097"'}, {'field': 'insert_data_option', 'description': 'Invalid value at \'insert_data_option\' (type.googleapis.com/google.apps.sheets.v4.InsertDataOption), "2"'}]}]}
INFO:root:1404452814 Artur Wed Mar  8 22:14:56 2023
INFO:aiogram:Bot: gmp_test [@gmp_test_bot]
INFO:aiogram.dispatcher.dispatcher:Start polling.
INFO:root:1404452814 Artur Wed Mar  8 22:18:42 2023
INFO:root:1404452814 Artur Wed Mar  8 22:19:08 2023
INFO:root:595835994 \u0410\u0434\u0435\u043b\u044f Wed Mar  8 22:20:33 2023
INFO:root:1404452814 Artur Wed Mar  8 22:34:00 2023
INFO:aiogram:Bot: gmp_test [@gmp_test_bot]
INFO:aiogram.dispatcher.dispatcher:Start polling.
INFO:root:1404452814 Artur Wed Mar  8 22:40:26 2023
INFO:root:1404452814 Artur Wed Mar  8 22:43:57 2023
INFO:aiogram:Bot: gmp_test [@gmp_test_bot]
INFO:aiogram.dispatcher.dispatcher:Start polling.
INFO:root:1404452814 Artur Sat Mar 11 22:43:06 2023
INFO:root:1404452814 Artur Sat Mar 11 22:51:36 2023
INFO:root:1404452814 Artur Sat Mar 11 23:15:53 2023
INFO:root:1404452814 Artur Sat Mar 11 23:17:04 2023
INFO:root:1404452814 Artur Sat Mar 11 23:24:14 2023
INFO:root:1404452814 Artur Sat Mar 11 23:27:57 2023
INFO:root:1404452814 Artur Sat Mar 11 23:28:44 2023
INFO:root:1404452814 Artur Sat Mar 11 23:33:49 2023
INFO:root:1404452814 Artur Sat Mar 11 23:35:03 2023
INFO:root:1404452814 Artur Sat Mar 11 23:36:33 2023
ERROR:asyncio:Task exception was never retrieved
future: <Task finished name='Task-467' coro=<Dispatcher._process_polling_updates() done, defined at c:\Python\telegram\GMP-Warranty_ID_bot\venv\lib\site-packages\aiogram\dispatcher\dispatcher.py:407> exception=UnboundLocalError("local variable 'warranty_state_dictionary' referenced before assignment")>
Traceback (most recent call last):
  File "c:\Python\telegram\GMP-Warranty_ID_bot\venv\lib\site-packages\aiogram\dispatcher\dispatcher.py", line 415, in _process_polling_updates
    for responses in itertools.chain.from_iterable(await self.process_updates(updates, fast)):
  File "c:\Python\telegram\GMP-Warranty_ID_bot\venv\lib\site-packages\aiogram\dispatcher\dispatcher.py", line 235, in process_updates
    return await asyncio.gather(*tasks)
  File "c:\Python\telegram\GMP-Warranty_ID_bot\venv\lib\site-packages\aiogram\dispatcher\handler.py", line 117, in notify
    response = await handler_obj.handler(*args, **partial_data)
  File "c:\Python\telegram\GMP-Warranty_ID_bot\venv\lib\site-packages\aiogram\dispatcher\dispatcher.py", line 256, in process_update
    return await self.message_handlers.notify(update.message)
  File "c:\Python\telegram\GMP-Warranty_ID_bot\venv\lib\site-packages\aiogram\dispatcher\handler.py", line 117, in notify
    response = await handler_obj.handler(*args, **partial_data)
  File "C:\Python\telegram\GMP-Warranty_ID_bot\GMP_W_B_main 1.3.py", line 124, in receive_ID_info
    print (warranty_state_dictionary)
UnboundLocalError: local variable 'warranty_state_dictionary' referenced before assignment
INFO:root:1404452814 Artur Sat Mar 11 23:39:32 2023
